ERROR:find-a-bug:'ncbi_genus'
ERROR:sqlalchemy.pool.impl.QueuePool:Exception during reset or similar
Traceback (most recent call last):
  File "/home/prichter/find-a-bug/env/lib64/python3.9/site-packages/sqlalchemy/pool/base.py", line 991, in _finalize_fairy
    fairy._reset(
  File "/home/prichter/find-a-bug/env/lib64/python3.9/site-packages/sqlalchemy/pool/base.py", line 1437, in _reset
    pool._dialect.do_rollback(self)
  File "/home/prichter/find-a-bug/env/lib64/python3.9/site-packages/sqlalchemy/engine/default.py", line 657, in do_rollback
    dbapi_connection.rollback()
  File "/home/prichter/find-a-bug/env/lib64/python3.9/site-packages/mariadb/connections.py", line 191, in rollback
    self._execute_command("ROLLBACK")
mariadb.InterfaceError: Server has gone away
ERROR:sqlalchemy.pool.impl.QueuePool:Exception during reset or similar
Traceback (most recent call last):
  File "/home/prichter/find-a-bug/env/lib64/python3.9/site-packages/sqlalchemy/sql/cache_key.py", line 243, in _gen_cache_key
    dispatcher = cls.__dict__["_generated_cache_key_traversal"]
KeyError: '_generated_cache_key_traversal'

During handling of the above exception, another exception occurred:

Traceback (most recent call last):
  File "/home/prichter/find-a-bug/env/lib64/python3.9/site-packages/sqlalchemy/pool/base.py", line 991, in _finalize_fairy
    fairy._reset(
  File "/home/prichter/find-a-bug/env/lib64/python3.9/site-packages/sqlalchemy/pool/base.py", line 1437, in _reset
    pool._dialect.do_rollback(self)
  File "/home/prichter/find-a-bug/env/lib64/python3.9/site-packages/sqlalchemy/engine/default.py", line 657, in do_rollback
    dbapi_connection.rollback()
  File "/home/prichter/find-a-bug/env/lib64/python3.9/site-packages/mariadb/connections.py", line 191, in rollback
    self._execute_command("ROLLBACK")
mariadb.InterfaceError: Server has gone away
