ERROR:find-a-bug:'NoneType' object has no attribute 'group_by'
ERROR:find-a-bug:'NoneType' object has no attribute 'group_by'
ERROR:find-a-bug:name 'value' is not defined
ERROR:find-a-bug:name 'value' is not defined
ERROR:find-a-bug:name 'value' is not defined
ERROR:find-a-bug:name 'url_query' is not defined
ERROR:find-a-bug:'FindABugQuery' object has no attribute 'col_to_table'
ERROR:find-a-bug:Could not reflect: requested table(s) not available in Engine(mariadb+mariadbconnector://root:***@localhost/findabug): (gtdb_r207_annotations_kegg)
ERROR:find-a-bug:(mariadb.ProgrammingError) Table 'findabug.gtdb_r207_annotations_kegg' doesn't exist
[SQL: SELECT gtdb_r207_annotations_kegg.ko, gtdb_r207_annotations_kegg.gene_name 
FROM gtdb_r207_annotations_kegg 
WHERE gtdb_r207_annotations_kegg.ko = ? 
 LIMIT ?, ?]
[parameters: ('K10670', 0, 100)]
(Background on this error at: https://sqlalche.me/e/20/f405)
ERROR:find-a-bug:(mariadb.ProgrammingError) Table 'findabug.gtdb_r207_annotations_kegg' doesn't exist
[SQL: SELECT gtdb_r207_annotations_kegg.ko, gtdb_r207_annotations_kegg.gene_name, gtdb_r207_annotations_kegg.genome_id 
FROM gtdb_r207_annotations_kegg 
WHERE gtdb_r207_annotations_kegg.ko = ? 
 LIMIT ?, ?]
[parameters: ('K10670', 0, 100)]
(Background on this error at: https://sqlalche.me/e/20/f405)
ERROR:find-a-bug:(mariadb.ProgrammingError) Table 'findabug.gtdb_r207_annotations_kegg' doesn't exist
[SQL: SELECT gtdb_r207_annotations_kegg.ko, gtdb_r207_annotations_kegg.gene_name, gtdb_r207_annotations_kegg.genome_id 
FROM gtdb_r207_annotations_kegg 
WHERE gtdb_r207_annotations_kegg.ko = ? 
 LIMIT ?, ?]
[parameters: ('K10670', 0, 100)]
(Background on this error at: https://sqlalche.me/e/20/f405)
ERROR:sqlalchemy.pool.impl.QueuePool:Exception during reset or similar
Traceback (most recent call last):
  File "/home/prichter/find-a-bug/env/lib64/python3.9/site-packages/sqlalchemy/pool/base.py", line 991, in _finalize_fairy
    fairy._reset(
  File "/home/prichter/find-a-bug/env/lib64/python3.9/site-packages/sqlalchemy/pool/base.py", line 1437, in _reset
    pool._dialect.do_rollback(self)
  File "/home/prichter/find-a-bug/env/lib64/python3.9/site-packages/sqlalchemy/engine/default.py", line 657, in do_rollback
    dbapi_connection.rollback()
  File "/home/prichter/find-a-bug/env/lib64/python3.9/site-packages/mariadb/connections.py", line 191, in rollback
    self._execute_command("ROLLBACK")
mariadb.InterfaceError: Server has gone away
ERROR:sqlalchemy.pool.impl.QueuePool:Exception during reset or similar
Traceback (most recent call last):
  File "/home/prichter/find-a-bug/env/lib64/python3.9/site-packages/sqlalchemy/pool/base.py", line 991, in _finalize_fairy
    fairy._reset(
  File "/home/prichter/find-a-bug/env/lib64/python3.9/site-packages/sqlalchemy/pool/base.py", line 1437, in _reset
    pool._dialect.do_rollback(self)
  File "/home/prichter/find-a-bug/env/lib64/python3.9/site-packages/sqlalchemy/engine/default.py", line 657, in do_rollback
    dbapi_connection.rollback()
  File "/home/prichter/find-a-bug/env/lib64/python3.9/site-packages/mariadb/connections.py", line 191, in rollback
    self._execute_command("ROLLBACK")
mariadb.InterfaceError: Server has gone away
ERROR:find-a-bug:(mariadb.ProgrammingError) Table 'findabug.gtdb_r207_annotations_kegg' doesn't exist
[SQL: SELECT gtdb_r207_annotations_kegg.ko, gtdb_r207_annotations_kegg.gene_name, gtdb_r207_annotations_kegg.genome_id 
FROM gtdb_r207_annotations_kegg 
WHERE gtdb_r207_annotations_kegg.ko = ? 
 LIMIT ?, ?]
[parameters: ('K10670', 0, 100)]
(Background on this error at: https://sqlalche.me/e/20/f405)
ERROR:find-a-bug:(mariadb.ProgrammingError) Table 'findabug.gtdb_r207_annotations_kegg' doesn't exist
[SQL: SELECT gtdb_r207_annotations_kegg.ko, gtdb_r207_annotations_kegg.gene_name, gtdb_r207_annotations_kegg.genome_id 
FROM gtdb_r207_annotations_kegg 
WHERE gtdb_r207_annotations_kegg.ko = ? 
 LIMIT ?, ?]
[parameters: ('K10670', 0, 100)]
(Background on this error at: https://sqlalche.me/e/20/f405)
ERROR:find-a-bug:(mariadb.InterfaceError) Server has gone away
[SQL: SHOW FULL TABLES FROM `findabug`]
(Background on this error at: https://sqlalche.me/e/20/rvf5)
ERROR:sqlalchemy.pool.impl.QueuePool:Exception during reset or similar
Traceback (most recent call last):
  File "/home/prichter/find-a-bug/env/lib64/python3.9/site-packages/sqlalchemy/pool/base.py", line 991, in _finalize_fairy
    fairy._reset(
  File "/home/prichter/find-a-bug/env/lib64/python3.9/site-packages/sqlalchemy/pool/base.py", line 1437, in _reset
    pool._dialect.do_rollback(self)
  File "/home/prichter/find-a-bug/env/lib64/python3.9/site-packages/sqlalchemy/engine/default.py", line 657, in do_rollback
    dbapi_connection.rollback()
  File "/home/prichter/find-a-bug/env/lib64/python3.9/site-packages/mariadb/connections.py", line 191, in rollback
    self._execute_command("ROLLBACK")
mariadb.InterfaceError: Server has gone away
ERROR:sqlalchemy.pool.impl.QueuePool:Exception during reset or similar
Traceback (most recent call last):
  File "/home/prichter/find-a-bug/env/lib64/python3.9/site-packages/sqlalchemy/pool/base.py", line 991, in _finalize_fairy
    fairy._reset(
  File "/home/prichter/find-a-bug/env/lib64/python3.9/site-packages/sqlalchemy/pool/base.py", line 1437, in _reset
    pool._dialect.do_rollback(self)
  File "/home/prichter/find-a-bug/env/lib64/python3.9/site-packages/sqlalchemy/engine/default.py", line 657, in do_rollback
    dbapi_connection.rollback()
  File "/home/prichter/find-a-bug/env/lib64/python3.9/site-packages/mariadb/connections.py", line 191, in rollback
    self._execute_command("ROLLBACK")
mariadb.InterfaceError: Server has gone away
ERROR:find-a-bug:handle() got an unexpected keyword argument 'resource'
ERROR:find-a-bug:handle() got an unexpected keyword argument 'resource'
ERROR:find-a-bug:'/annotations'
ERROR:find-a-bug:'/annotation'
ERROR:find-a-bug:unsupported operand type(s) for +: 'set' and 'list'
ERROR:find-a-bug:unsupported operand type(s) for +: 'set' and 'set'
ERROR:find-a-bug:Textual column expression 'gtdb_r207_annotations_keg...' should be explicitly declared with text('gtdb_r207_annotations_keg...'), or use column('gtdb_r207_annotations_keg...') for more specificity
ERROR:find-a-bug:get_query_tables() takes 1 positional argument but 2 were given
ERROR:find-a-bug:name 'get_fields' is not defined
ERROR:find-a-bug:name 'get_fields' is not defined
ERROR:find-a-bug:'str' object has no attribute '__tablename__'
